##### 关于promise

     promise.then 第二个回调函数：可以捕获then之前的错误，不能捕获then同级和之后的错误
     promise.catch 捕获catch之前的错误
     promise.done   
     promise.finally finally接收的是普通函数，不带参数，promise链式调用停止
     
##### 各种错误捕获方式

常见的异常场景：

    JS 语法错误、代码异常
    AJAX 请求异常
    静态资源加载异常
    Promise 异常
    Iframe 异常
    跨域 Script error
    崩溃和卡顿

http://jartto.wang/2018/11/20/js-exception-handling/

###### 1、window.onerror

无法捕获语法错误、网络请求错误（但是计时器这些异常是可以捕捉的）、资源加载错误

可处理iframe异常

###### 2、window.addEventListener('error', function(e) {}, true)

可以捕获资源加载异常（只有在设置为true时才能监听资源异常），捕获异步的网络错误

无法捕获语法错误

###### 3、window.addEventListener('unhandledrejection', function() {})

未catch的promise异常捕获

###### 4、try {} catch (e) {}

无法捕获异步异常，无法监控资源加载错误
无法捕获语法错误

##### promise的finally和try catch的finally的区别 - 是否能够return

    function f() {
        new Promise(function (resolve, reject) {
    
        })
            .finally(function () {
                return 1;
            })
    }
    
    function f1() {
        try{}
        catch (e) {
    
        }
        finally {
            return 22
        }
    }
    
    console.log(f());
    console.log(f1());
    
##### promise中的计时器抛错如何去处理

    如
    new Promise(function() {
        setTimeout(function(){
            throw new Error();
        },0)
    })
    .catch(function(e) {
        console.log(e);
    })
    --> 此时catch的错误是无法被catch捕获到的，因为setTimeout异步执行，
    而promise捕获错误机制是先要隐式try catch再将promise的状态转化为rejected
    然后到catch。而在js运行时，try catch是无法捕获到异步错误的
    
    正确的做法可以是：
        new Promise(function(resolve, reject){
            setTimeout(function(){
                try{
                    throw new Error();
                }catch(e) {
                    reject(e);
                }
            },0)
        })
            .catch(function(e){
                console.log(e);
            })
            
